Workbook

Sheet PRISMA Dashboard
A1: IDENTIFICATION
A2: Records identified (databases) | B2: 793
A3: Scopus / IEEE / arXiv | B3: 451 / 237 / 105
A4: Duplicates removed before screening | B4: 241
A5: automated (216) + manual (25) | B5: 216 + 25
A7: SCREENING (Stage 1: title/abstract)
A8: Records screened | B8: =COUNTA(Screening!B2:B548) -> 547
A9: Included | B9: =COUNTIF(Screening!G2:G548,"Include") -> 203
A10: Maybe (carry forward) | B10: =COUNTIF(Screening!G2:G548,"Maybe") -> 67
A11: Excluded | B11: =COUNTIF(Screening!G2:G548,"Exclude") -> 277
A12: Not yet screened | B12: =COUNTA(Screening!B2:B548)-COUNTA(Screening!G2:G548) -> 0
A13: Reports sought for retrieval (Include+Maybe) | B13: =COUNTIF(Screening!G2:G548,"Include")+COUNTIF(Screening!G2:G548,"Maybe") -> 270
A15: Stage 1 exclusions by reason
A16: EC1 | B16: =COUNTIFS(Screening!G2:G548,"Exclude",Screening!H2:H548,"EC1") -> 0
A17: EC2 | B17: =COUNTIFS(Screening!G2:G548,"Exclude",Screening!H2:H548,"EC2") -> 0
A18: EC3 | B18: =COUNTIFS(Screening!G2:G548,"Exclude",Screening!H2:H548,"EC3") -> 42
A19: EC4 | B19: =COUNTIFS(Screening!G2:G548,"Exclude",Screening!H2:H548,"EC4") -> 138
A20: EC5 | B20: =COUNTIFS(Screening!G2:G548,"Exclude",Screening!H2:H548,"EC5") -> 36
A21: EC6 | B21: =COUNTIFS(Screening!G2:G548,"Exclude",Screening!H2:H548,"EC6") -> 10
A22: EC7 | B22: =COUNTIFS(Screening!G1:G547,"Exclude",Screening!H1:H547,"EC7") -> 51
A23: EC8 | B23: =COUNTIFS(Screening!G2:G548,"Exclude",Screening!H2:H548,"EC7") -> 51
A26: ELIGIBILITY (Stage 2: full text)
A27: Reports assessed for eligibility | B27: =COUNTA(Screening!I2:I548) -> 76
A28: Excluded (full text) | B28: =COUNTIF(Screening!I2:I548,"Exclude") -> 69
A29: Studies INCLUDED in review | B29: =COUNTIF(Screening!I2:I548,"Include") -> 6
A30: Total Remaining | B30: =B13-B27 -> 194
A31: Total in WIP List [Zotero] | B31: =B30+B29 -> 200
A33: Stage 2 exclusions by reason
A34: EC1 | B34: =COUNTIFS(Screening!I2:I548,"Exclude",Screening!J2:J548,"EC1") -> 1
A35: EC2 | B35: =COUNTIFS(Screening!I2:I548,"Exclude",Screening!J2:J548,"EC2") -> 0
A36: EC3 | B36: =COUNTIFS(Screening!I2:I548,"Exclude",Screening!J2:J548,"EC3") -> 3
A37: EC4 | B37: =COUNTIFS(Screening!I2:I548,"Exclude",Screening!J2:J548,"EC4") -> 3
A38: EC5 | B38: =COUNTIFS(Screening!I2:I548,"Exclude",Screening!J2:J548,"EC5") -> 0
A39: EC6 | B39: =COUNTIFS(Screening!I2:I548,"Exclude",Screening!J2:J548,"EC6") -> 0
A40: EC7 | B40: =COUNTIFS(Screening!I3:I549,"Exclude",Screening!J3:J549,"EC7") -> 7
A41: EC8 | B41: =COUNTIFS(Screening!I4:I550,"Exclude",Screening!J4:J550,"EC8") -> 54

Sheet Screening
A1: # | B1: Title | C1: Authors | D1: Venue | E1: Type | F1: DOI | G1: Stage1 Decision | H1: Stage1 Reason | I1: Stage2 Decision | J1: Stage2 Reason | K1: Abstract | L1: Application domain | M1: Notes | N1: URL
A2: 1 | B2: Quantum-Enhanced Water Quality Monitoring: Exploiting Phi-Sat-2 Data With Quanvolution | C2: F. Mauro; F. Razzano; P. D. Stasio; A. Sebastianelli; G. Meoni; G. Schirinzi; P. Gamba; S. L. Ullo | D2: IEEE (corrupted source record - verify DOI/year) | E2: article | G2: Exclude | H2: EC4 | K2: Coastal water quality monitoring is crucial for environmental sustainability and public health. This work introduces a very cutting-edge methodology, using Φ Sat-2 multispectral data and quanvolutional neural networks (QNNs) to explore quantum-enhanced machine learning (ML) for water contaminant assessment. By integrating quantum preprocessing into a classical regression model, it is possible to achieve a significant reduction in model parameters while maintaining high predictive accuracy. In addition, this work introduces an innovative dataset that integrates simulated Φ Sat-2 spectral data with Copernicus Marine Service biogeochemical products, ensuring a strong alignment between satellite observations and reference turbidity measurements. Our results show that quantum models use up to 98% fewer parameters than their classical counterparts, while achieving a 6.9% improvement in the Pearson correlation coefficient between the Φ Sat-2 preprocessed bands and the ground-truth turbidity values, compared with the case without quantum preprocessing. In addition, the root mean square error (RMSE) improves by 7.3% over the classical baseline. These findings highlight the potential of quantum-assisted remote sensing (RS) to enable more efficient and scalable analysis of large-scale water contaminant data, paving the way for advanced big data approaches in water quality monitoring.
A3: 2 | B3: Absence of Barren Plateaus in Quantum Convolutional Neural Networks | C3: Arthur Pesah and M Cerezo and Samson Wang and Tyler Volkoff and Andrew T Sornborger and Patrick J Coles | D3: Phys. Rev. X 11, 041011 (2021) | E3: article | F3: 10.1103/PhysRevX.11.041011 | G3: Exclude | H3: EC5 | K3: Quantum neural networks (QNNs) have generated excitement around the possibility of efficiently analyzing quantum data. But this excitement has been tempered by the existence of exponentially vanishing gradients, known as barren plateau landscapes, for many QNN architectures. Recently, Quantum Convolutional Neural Networks (QCNNs) have been proposed, involving a sequence of convolutional and pooling layers that reduce the number of qubits while preserving information about relevant data features. In this work we rigorously analyze the gradient scaling for the parameters in the QCNN architecture. We find that the variance of the gradient vanishes no faster than polynomially, implying that QCNNs do not exhibit barren plateaus. This provides an analytical guarantee for the trainability of randomly initialized QCNNs, which highlights QCNNs as being trainable under random initialization unlike many other QNN architectures. To derive our results we introduce a novel graph-based method to analyze expectation values over Haar-distributed unitaries, which will likely be useful in other contexts. Finally, we perform numerical simulations to verify our analytical results. | N3: http://arxiv.org/abs/2011.02966v2
A4: 3 | B4: Hybrid Quantum-Classical Graph Convolutional Network | C4: Samuel Yen-Chi Chen and Tzu-Chieh Wei and Chao Zhang and Haiwang Yu and Shinjae Yoo | E4: misc | G4: Exclude | H4: EC4 | K4: The high energy physics (HEP) community has a long history of dealing with large-scale datasets. To manage such voluminous data, classical machine learning and deep learning techniques have been employed to accelerate physics discovery. Recent advances in quantum machine learning (QML) have indicated the potential of applying these techniques in HEP. However, there are only limited results in QML applications currently available. In particular, the challenge of processing sparse data, common in HEP datasets, has not been extensively studied in QML models. This research provides a hybrid quantum-classical graph convolutional network (QGCNN) for learning HEP data. The proposed framework demonstrates an advantage over classical multilayer perceptron and convolutional neural networks in the aspect of number of parameters. Moreover, in terms of testing accuracy, the QGCNN shows comparable performance to a quantum convolutional neural network on the same HEP dataset while requiring less than $50\%$ of the parameters. Based on numerical simulation results, studying the application of graph convolutional operations and other QML models may prove promising in advancing HEP research and other scientific fields. | N4: http://arxiv.org/abs/2101.06189v1
A5: 4 | B5: Analyzing the barren plateau phenomenon in training quantum neural networks with the ZX-calculus | C5: Chen Zhao and Xiao-Shan Gao | D5: Quantum 5, 466 (2021) | E5: article | F5: 10.22331/q-2021-06-04-466 | G5: Exclude | H5: EC4 | K5: In this paper, we propose a general scheme to analyze the gradient vanishing phenomenon, also known as the barren plateau phenomenon, in training quantum neural networks with the ZX-calculus. More precisely, we extend the barren plateaus theorem from unitary 2-design circuits to any parameterized quantum circuits under certain reasonable assumptions. The main technical contribution of this paper is representing certain integrations as ZX-diagrams and computing them with the ZX-calculus. The method is used to analyze four concrete quantum neural networks with different structures. It is shown that, for the hardware efficient ansatz and the MPS-inspired ansatz, there exist barren plateaus, while for the QCNN ansatz and the tree tensor network ansatz, there exists no barren plateau. | N5: http://arxiv.org/abs/2102.01828v2
A6: 318 | B6: (Formula presented): Exploration of Quantum Deep Learning on Humanities Data from the Perspective of Digital Humanities | C6: Tao Fan and Hao Wang and Tobias Hodel | D6: Social Science Computer Review | E6: article | F6: 10.1177/08944393261416783 | G6: Maybe | H6: Verify QCNN usage and results | I6: Exclude | J6: EC8 | K6: The emergence and advancement of new technologies present promising opportunities for data-driven research in the Digital Humanities (DH). As an innovative intersection of quantum computing and humanities data, Quantum Humanities (QH) holds significant research potential. However, current studies related to QH remain scarce with limited applications involving quantum deep learning, and its feasibility, effectiveness, and efficiency on humanities data need in-depth exploration. To address this gap, this paper takes the role type recognition of painted faces of Beijing Opera as a case study. Several classical and competitive quantum deep learning–based and classical deep learning–based models (e.g., quantum convolutional neural networks and classical convolutional neural networks) are selected for comparison on the public image dataset Painted Faces of Beijing Opera digitized from books. Extensive empirical experimental results demonstrate that quantum deep learning–based models are of certain advantages and hold promising prospects in applied DH practices. © The Author(s) 2026
A7: 13 | B7: 3D Scalable Quantum Convolutional Neural Networks for Point Cloud Data Processing in Classification Applications | C7: Hankyul Baek and Won Joon Yun and Joongheon Kim | E7: misc | G7: Include | H7: QCNN Variant with a use-case/application domain (Point Cloud Data Processing) | I7: Include | J7: Passed by Mahmoud | K7: With the beginning of the noisy intermediate-scale quantum (NISQ) era, a quantum neural network (QNN) has recently emerged as a solution for several specific problems that classical neural networks cannot solve. Moreover, a quantum convolutional neural network (QCNN) is the quantum-version of CNN because it can process high-dimensional vector inputs in contrast to QNN. However, due to the nature of quantum computing, it is difficult to scale up the QCNN to extract a sufficient number of features due to barren plateaus. Motivated by this, a novel 3D scalable QCNN (sQCNN-3D) is proposed for point cloud data processing in classification applications. Furthermore, reverse fidelity training (RF-Train) is additionally considered on top of sQCNN-3D for diversifying features with a limited number of qubits using the fidelity of quantum computing. Our data-intensive performance evaluation verifies that the proposed algorithm achieves desired performance. | N7: http://arxiv.org/abs/2210.09728v1
A8: 7 | B8: Variational Quanvolutional Neural Networks with enhanced image encoding | C8: Denny Mattern and Darya Martyniuk and Henri Willems and Fabian Bergmann and Adrian Paschke | E8: misc | G8: Exclude | H8: EC4 | K8: Image classification is an important task in various machine learning applications. In recent years, a number of classification methods based on quantum machine learning and different quantum image encoding techniques have been proposed. In this paper, we study the effect of three different quantum image encoding approaches on the performance of a convolution-inspired hybrid quantum-classical image classification algorithm called quanvolutional neural network (QNN). We furthermore examine the effect of variational - i.e. trainable - quantum circuits on the classification results. Our experiments indicate that some image encodings are better suited for variational circuits. However, our experiments show as well that there is not one best image encoding, but that the choice of the encoding depends on the specific constraints of the application. | N8: http://arxiv.org/abs/2106.07327v2
A9: 8 | B9: Generalization in quantum machine learning from few training data | C9: Matthias C Caro and Hsin-Yuan Huang and M Cerezo and Kunal Sharma and Andrew Sornborger and Lukasz Cincio and Patrick J Coles | D9: Nat Commun 13, 4919 (2022) | E9: article | F9: 10.1038/s41467-022-32550-3 | G9: Exclude | H9: EC5 | K9: Modern quantum machine learning (QML) methods involve variationally optimizing a parameterized quantum circuit on a training data set, and subsequently making predictions on a testing data set (i.e., generalizing). In this work, we provide a comprehensive study of generalization performance in QML after training on a limited number $N$ of training data points. We show that the generalization error of a quantum machine learning model with $T$ trainable gates scales at worst as $\sqrt{T/N}$. When only $K \ll T$ gates have undergone substantial change in the optimization process, we prove that the generalization error improves to $\sqrt{K / N}$. Our results imply that the compiling of unitaries into a polynomial number of native gates, a crucial application for the quantum computing industry that typically uses exponential-size training data, can be sped up significantly. We also show that classification of quantum states across a phase transition with a quantum convolutional neural network requires only a very small training data set. Other potential applications include learning quantum error correcting codes or quantum dynamical simulation. Our work injects new hope into the field of QML, as good generalization is guaranteed from few training data. | N9: http://arxiv.org/abs/2111.05292v2
A10: 9 | B10: Multiclass classification using quantum convolutional neural networks with hybrid quantum-classical learning | C10: Denis Bokhan and Alena S Mastiukova and Aleksey S Boev and Dmitrii N Trubnikov and Aleksey K Fedorov | D10: Front. Phys. 10, 1069985 (2022) | E10: article | F10: 10.3389/fphy.2022.1069985 | G10: Exclude | H10: EC5 | K10: Multiclass classification is of great interest for various applications, for example, it is a common task in computer vision, where one needs to categorize an image into three or more classes. Here we propose a quantum machine learning approach based on quantum convolutional neural networks for solving the multiclass classification problem. The corresponding learning procedure is implemented via TensorFlowQuantum as a hybrid quantum-classical (variational) model, where quantum output results are fed to the softmax activation function with the subsequent minimization of the cross entropy loss via optimizing the parameters of the quantum circuit. Our conceptional improvements here include a new model for a quantum perceptron and an optimized structure of the quantum circuit. We use the proposed approach to solve a 4-class classification problem for the case of the MNIST dataset using eight qubits for data encoding and four ancilla qubits; previous results have been obtained for 3-class classification problems. Our results show that accuracies of our solution are similar to classical convolutional neural networks with comparable numbers of trainable parameters. We expect that our finding provide a new step towards the use of quantum neural networks for solving relevant problems in the NISQ era and beyond. | N10: http://arxiv.org/abs/2203.15368v2
A11: 10 | B11: Predict better with less training data using a QNN | C11: Barry D Reese and Marek Kowalik and Christian Metzl and Christian Bauckhage and Eldar Sultanow | E11: misc | G11: Exclude | H11: EC4 | K11: Over the past decade, machine learning revolutionized vision-based quality assessment for which convolutional neural networks (CNNs) have now become the standard. In this paper, we consider a potential next step in this development and describe a quanvolutional neural network (QNN) algorithm that efficiently maps classical image data to quantum states and allows for reliable image analysis. We practically demonstrate how to leverage quantum devices in computer vision and how to introduce quantum convolutions into classical CNNs. Dealing with a real world use case in industrial quality control, we implement our hybrid QNN model within the PennyLane framework and empirically observe it to achieve better predictions using much fewer training data than classical CNNs. In other words, we empirically observe a genuine quantum advantage for an industrial application where the advantage is due to superior data encoding. | N11: http://arxiv.org/abs/2206.03960v1
A12: 11 | B12: Case study on quantum convolutional neural network scalability | C12: Marina O Lisnichenko and Stanislav I Protasov | E12: misc | G12: Exclude | H12: EC5 | K12: One of the crucial tasks in computer science is the processing time reduction of various data types, i.e., images, which is important for different fields -- from medicine and logistics to virtual shopping. Compared to classical computers, quantum computers are capable of parallel data processing, which reduces the data processing time. This quality of quantum computers inspired intensive research of the potential of quantum technologies applicability to real-life tasks. Some progress has already revealed on a smaller volumes of the input data. In this research effort, I aimed to increase the amount of input data (I used images from 2 x 2 to 8 x 8), while reducing the processing time, by way of skipping intermediate measurement steps. The hypothesis was that, for increased input data, the omitting of intermediate measurement steps after each quantum convolution layer will improve output metric results and accelerate data processing. To test the hypothesis, I performed experiments to chose the best activation function and its derivative in each network. The hypothesis was partly confirmed in terms of output mean squared error (MSE) -- it dropped from 0.25 in the result of classical convolutional neural network (CNN) training to 0.23 in the result of quantum convolutional neural network (QCNN) training. In terms of the training time, however, which was 1.5 minutes for CNN and 4 hours 37 minutes in the least lengthy training iteration, the hypothesis was rejected. | N12: http://arxiv.org/abs/2207.07160v1
A13: 482 | B13: A Comparative Analysis of Hybrid Quantum Neural Networks in Binary Credit Defaulting Tasks | C13: Aditya Sengar and Aarya Vijayaraghavan and Jiwoo Hwang | D13: IEEE MIT Undergraduate Research Technology Conference, URTC 2023 - Proceedings | E13: inproceedings | F13: 10.1109/URTC60662.2023.10535032 | G13: Maybe | H13: QCNN used to create financial analytical models | I13: Exclude | J13: EC4 | K13: Quantum machine learning has been shown to offer exponential computational boosts compared to current classical models through the exploitation of quantum mechanical properties such as entanglement and superposition. The finance sub field of fin-Tech, where financial services are constructed around a customer's demands, is believed to benefit with the use of hybrid quantum-classical machine learning algorithms. Classical algorithms struggle to create accurate, complex, and prompt financial analytical models resulting in over 25% of small and medium sized financial institutions losing customers each year. This study explores whether a hybrid quantum neural network (QCNN) design provides a quantum advantage in either accuracy or time in the fin tech task of credit defaulting. The hybrid quantum neural network model uses a variational quantum circuit built on a continuous variable architecture. The data flow of the network consists of a classical network, quantum data encoding (which uses quantum squeezers, interferometers, displacement, and Kerr gates), QCNN, and measurement. Although the quantum model took a longer time to train, it reported a higher prediction accuracy of 97.63% compared to 91.20% for the classical network. This work demonstrates the future implications of quantum integration in the financial field and the quantum advantage it offers on classification tasks. © 2023 IEEE.
A14: 460 | B14: A Comparative Study of Classical and Quantum Machine Learning Techniques for Industrial Defect Classification | C14: Antimo Angelino and Daniele D'Amato and Gennaro Galante and Enrico Landolfi and Alfredo Massa and Alfredo Troiano | D14: Proceedings - 2025 IEEE International Conference on Quantum Artificial Intelligence, QAI 2025 | E14: inproceedings | F14: 10.1109/QAI63978.2025.00074 | G14: Include | H14: QCNN for Industrial Defect Classification | I14: Include | J14: Passed by Mahmoud | K14: This work presents a comparative evaluation of classical and quantum machine learning models applied to a real-world industrial classification task. The use case is provided by MBDA and involves classifying images of surface-mount technology solder joints into three defect severity classes. To investigate the viability and performance trade-offs of quantum models under realistic constraints, we followed two parallel processing strategies. The first employs conventional deep learning architectures, namely YOLOv8 and a custom Convolutional Neural Network (CNN), trained on augmented full-resolution images. The second strategy compresses image data via a domainspecific method, enabling compatibility with quantum hardware constraints. We trained and evaluated different quantum machine learning models, including a Quantum Support Vector Machine (QSVM), a Variational Quantum Classifier (VQC), and a Quantum Convolutional Neural Network (QCNN). Our results highlight the trade-offs between expressivity and feasibility across classical and quantum approaches and provide insights into the applicability of quantum models in industrial scenarios. © 2025 IEEE.
A15: 408 | B15: A complex-valued embedding and quantum convolutional neural network-based fake news detection method | C15: Jiacheng Tang and Lianhe Shao and Quanli Gao and Xihan Wang | D15: Proceedings of SPIE - The International Society for Optical Engineering | E15: inproceedings | F15: 10.1117/12.3075824 | G15: Include | H15: QCNN used for Fake News Detection | I15: Exclude | J15: EC8 | K15: Recently, fake news has been on the rise, seriously affecting public perception and personal decision-making. Given that online fake news often contains multimedia elements, such information is more misleading than fake news in purely textual form and can spread more widely, it is significant to study multimodal fake news detection. However, the existing detection methods have a few problems: 1) The current tactics with better detection effect usually use Transformer to extract text features, which leads to insufficient extraction of news text features. 2) The existing methods usually use a cascade method to splice modal features and then directly feed them into the classifier, which leads to unsatisfactory detection results. Aiming at the above problems, we propose a quantum-inspired fake news detection method (CQFND). Specifically, the word embedding representation of the input text is converted to a complex form by using a complex-valued embedding layer (ComplexEmbedding) and weighted summation, and the text's feature representation is derived by weighted aggregation. The news image features are obtained by ViT, the two are vector spliced, and the results are processed by the introduced QCNN to finally obtain the detection results. The CQFND model is tested against other classical models on public datasets, and the results confirm that our approach outperforms others on some common indicators. © 2025 SPIE.
A16: 87 | B16: A Deep Quantum Convolutional Neural Network Based Facial Expression Recognition For Mental Health Analysis | C16: S Hossain and S Umer and R K Rout and H A Marzouqi | D16: IEEE Transactions on Neural Systems and Rehabilitation Engineering | E16: article | F16: 10.1109/TNSRE.2024.3385336 | G16: Include | H16: QCNN on Facial Expression Recognition | I16: Include | J16: Passed by Mahmoud | K16: The purpose of this work is to analyze how new technologies can enhance clinical practice while also examining the physical traits of emotional expressiveness of face expression in a number of psychiatric illnesses. Hence, in this work, an automatic facial expression recognition system has been proposed that analyzes static, sequential, or video facial images from medical healthcare data to detect emotions in people's facial regions. The proposed method has been implemented in five steps. The first step is image preprocessing, where a facial region of interest has been segmented from the input image. The second component includes a classical deep feature representation and the quantum part that involves successive sets of quantum convolutional layers followed by random quantum variational circuits for feature learning. Here, the proposed system has attained a faster training approach using the proposed quantum convolutional neural network approach that takes $\mathbb \{O\}\{(\}\text \{log\}\{(\}\{n\}\{)\}\{)\}$ time. In contrast, the classical convolutional neural network models have $\mathbb \{O\}\{(\}\{n\}^\{\{2\}\}\{)\}$ time. Additionally, some performance improvement techniques, such as image augmentation, fine-tuning, matrix normalization, and transfer learning methods, have been applied to the recognition system. Finally, the scores due to classical and quantum deep learning models are fused to improve the performance of the proposed method. Extensive experimentation with Karolinska-directed emotional faces (KDEF), Static Facial Expressions in the Wild (SFEW 2.0), and Facial Expression Recognition 2013 (FER-2013) benchmark databases and compared with other state-of-the-art methods that show the improvement of the proposed system.
A17: 31 | B17: A Distributed Hybrid Quantum Convolutional Neural Network for Medical Image Classification | C17: Yangyang Li and Zhengya Qia and Yuelin Lia and Haorui Yanga and Ronghua Shanga and Licheng Jiaoa | E17: misc | G17: Include | H17: Medical QCNN | I17: Include | J17: Passed by Mahmoud | K17: Medical images are characterized by intricate and complex features, requiring interpretation by physicians with medical knowledge and experience. Classical neural networks can reduce the workload of physicians, but can only handle these complex features to a limited extent. Theoretically, quantum computing can explore a broader parameter space with fewer parameters, but it is currently limited by the constraints of quantum hardware.Considering these factors, we propose a distributed hybrid quantum convolutional neural network based on quantum circuit splitting. This model leverages the advantages of quantum computing to effectively capture the complex features of medical images, enabling efficient classification even in resource-constrained environments. Our model employs a quantum convolutional neural network (QCNN) to extract high-dimensional features from medical images, thereby enhancing the model's expressive capability.By integrating distributed techniques based on quantum circuit splitting, the 8-qubit QCNN can be reconstructed using only 5 qubits.Experimental results demonstrate that our model achieves strong performance across 3 datasets for both binary and multiclass classification tasks. Furthermore, compared to recent technologies, our model achieves superior performance with fewer parameters, and experimental results validate the effectiveness of our model. | N17: http://arxiv.org/abs/2501.06225v1
A18: 17 | B18: Quaternion Convolutional Neural Networks: Current Advances and Future Directions | C18: Gerardo Altamirano-Gomez and Carlos Gershenson | D18: Advances in Applied Clifford Algebras, 34(4):42, 2024 | E18: article | F18: 10.1007/s00006-024-01350-x | G18: Exclude | H18: EC4 | K18: Since their first applications, Convolutional Neural Networks (CNNs) have solved problems that have advanced the state-of-the-art in several domains. CNNs represent information using real numbers. Despite encouraging results, theoretical analysis shows that representations such as hyper-complex numbers can achieve richer representational capacities than real numbers, and that Hamilton products can capture intrinsic interchannel relationships. Moreover, in the last few years, experimental research has shown that Quaternion-Valued CNNs (QCNNs) can achieve similar performance with fewer parameters than their real-valued counterparts. This paper condenses research in the development of QCNNs from its very beginnings. We propose a conceptual organization of current trends and analyze the main building blocks used in the design of QCNN models. Based on this conceptual organization, we propose future directions of research. | N18: http://arxiv.org/abs/2307.08663v1
A19: 18 | B19: A Post-Training Approach for Mitigating Overfitting in Quantum Convolutional Neural Networks | C19: Aakash Ravindra Shinde and Charu Jain and Amir Kalev | D19: Phys Rev A 110 042409 (2024) | E19: article | F19: 10.1103/PhysRevA.110.042409 | G19: Exclude | H19: EC5 | K19: Quantum convolutional neural network (QCNN), an early application for quantum computers in the NISQ era, has been consistently proven successful as a machine learning (ML) algorithm for several tasks with significant accuracy. Derived from its classical counterpart, QCNN is prone to overfitting. Overfitting is a typical shortcoming of ML models that are trained too closely to the availed training dataset and perform relatively poorly on unseen datasets for a similar problem. In this work we study post-training approaches for mitigating overfitting in QCNNs. We find that a straightforward adaptation of a classical post-training method, known as neuron dropout, to the quantum setting leads to a significant and undesirable consequence: a substantial decrease in success probability of the QCNN. We argue that this effect exposes the crucial role of entanglement in QCNNs and the vulnerability of QCNNs to entanglement loss. Hence, we propose a parameter adaptation method as an alternative method. Our method is computationally efficient and is found to successfully handle overfitting in the test cases. | N19: http://arxiv.org/abs/2309.01829v2
A20: 19 | B20: Quantum Inception Score | C20: Akira Sone and Akira Tanji and Naoki Yamamoto | D20: Phys. Rev. Research 6, 033198 (2024) | E20: article | F20: 10.1103/PhysRevResearch.6.033198 | G20: Exclude | H20: EC4 | K20: Motivated by the great success of classical generative models in machine learning, enthusiastic exploration of their quantum version has recently started. To depart on this journey, it is important to develop a relevant metric to evaluate the quality of quantum generative models; in the classical case, one such example is the (classical) inception score (cIS). In this paper, as a natural extension of cIS, we propose the quantum inception score (qIS) for quantum generators. Importantly, qIS relates the quality to the Holevo information of the quantum channel that classifies a given dataset. In this context, we show several properties of qIS. First, qIS is greater than or equal to the corresponding cIS, which is defined through projection measurements on the system output. Second, the difference between qIS and cIS arises from the presence of quantum coherence, as characterized by the resource theory of asymmetry. Third, when a set of entangled generators is prepared, there exists a classifying process leading to the further enhancement of qIS. Fourth, we harness the quantum fluctuation theorem to characterize the physical limitation of qIS. Finally, we apply qIS to assess the quality of the one-dimensional spin chain model as a quantum generative model, with the quantum convolutional neural network as a quantum classifier, for the phase classification problem in the quantum many-body physics. | N20: http://arxiv.org/abs/2311.12163v4
A21: 20 | B21: Impact of Data Augmentation on QCNNs | C21: Leting Zhouli and Peiyong Wang and Udaya Parampalli | E21: misc | G21: Exclude | H21: EC7 | K21: In recent years, Classical Convolutional Neural Networks (CNNs) have been applied for image recognition successfully. Quantum Convolutional Neural Networks (QCNNs) are proposed as a novel generalization to CNNs by using quantum mechanisms. The quantum mechanisms lead to an efficient training process in QCNNs by reducing the size of input from $N$ to $log_2N$. This paper implements and compares both CNNs and QCNNs by testing losses and prediction accuracy on three commonly used datasets. The datasets include the MNIST hand-written digits, Fashion MNIST and cat/dog face images. Additionally, data augmentation (DA), a technique commonly used in CNNs to improve the performance of classification by generating similar images based on original inputs, is also implemented in QCNNs. Surprisingly, the results showed that data augmentation didn't improve QCNNs performance. The reasons and logic behind this result are discussed, hoping to expand our understanding of Quantum machine learning theory. | N21: http://arxiv.org/abs/2312.00358v1
A22: 118 | B22: A Hybrid Quantum-Classical Approach for Multi-Class Skin Disease Classification Using a 4-Qubit Model | C22: Aravinda and Emerson Raja Joseph and Sultan Alasmari | D22: IEEE Access | E22: article | F22: 10.1109/ACCESS.2025.3581030 | G22: Include | H22: QCNN against Q-C Skin Disease Classification | K22: Quantum machine learning (QML) presents a promising avenue for addressing complex classification challenges, yet its application in medical imaging remains largely unexplored. This work introduces a hybrid quantum-classical framework designed to classify skin diseases, Chickenpox, Measles, Monkeypox, and Normal, using a 4 qubit quantum system. The framework integrates a Quantum Convolutional Neural Network (QCNN) for feature extraction and a Variational Quantum Classifier (VQC) for classification, processing a dataset of 770 images with significant class imbalance. We employ a class-weighted loss function with weights wyi = [3.0, 3.5, 0.6, 0.4] to address this imbalance, ensuring balanced representation across all classes. The model is optimized using Simultaneous Perturbation Stochastic Approximation (SPSA) over 150 iterations, achieving a test accuracy 70.13% on a subset of 154 images, representing 20% of the dataset. This marks a substantial improvement over both a random baseline of 25% and a prior run that achieved 37.66% accuracy, which was skewed toward the majority class. Principal Component Analysis (PCA) reduces image features to a 4-dimensional representation, enabling compatibility with the quantum system. The QCNN extracts these features, while the VQC performs classification based on measurements from 1024 shots on the QASM simulator. To ensure practical reusability, the trained model, including quantum circuits, optimized parameters, and PCA transformations, is saved for future deployment. Validation on a separate set of 24 samples (6 per class) yields 70.83% accuracy (17 out of 24 correct predictions), demonstrating the model’s generalization capabilities. While the performance falls short of classical benchmarks, this study establishes the feasibility of QML with minimal qubits, paving the way for quantum driven diagnostics in resource constrained environments. © 2013 IEEE.
A23: 22 | B23: ResQuNNs: Towards Enabling Deep Learning in Quantum Convolution Neural Networks | C23: Muhammad Kashif and Muhammad Shafique | D23: Scientific Reports 15, no. 1 (2025) | E23: article | F23: 10.1038/s41598-025-06035-4 | G23: Exclude | H23: EC4 | K23: In this paper, we present a novel framework for enhancing the performance of Quanvolutional Neural Networks (QuNNs) by introducing trainable quanvolutional layers and addressing the critical challenges associated with them. Traditional quanvolutional layers, although beneficial for feature extraction, have largely been static, offering limited adaptability. Unlike state-of-the-art, our research overcomes this limitation by enabling training within these layers, significantly increasing the flexibility and potential of QuNNs. However, the introduction of multiple trainable quanvolutional layers induces complexities in gradient-based optimization, primarily due to the difficulty in accessing gradients across these layers. To resolve this, we propose a novel architecture, Residual Quanvolutional Neural Networks (ResQuNNs), leveraging the concept of residual learning, which facilitates the flow of gradients by adding skip connections between layers. By inserting residual blocks between quanvolutional layers, we ensure enhanced gradient access throughout the network, leading to improved training performance. Moreover, we provide empirical evidence on the strategic placement of these residual blocks within QuNNs. Through extensive experimentation, we identify an efficient configuration of residual blocks, which enables gradients across all the layers in the network that eventually results in efficient training. Our findings suggest that the precise location of residual blocks plays a crucial role in maximizing the performance gains in QuNNs. Our results mark a substantial step forward in the evolution of quantum deep learning, offering new avenues for both theoretical development and practical quantum computing applications. | N23: http://arxiv.org/abs/2402.09146v6
A24: 23 | B24: Multi-GPU-Enabled Hybrid Quantum-Classical Workflow in Quantum-HPC Middleware: Applications in Quantum Simulations | C24: Kuan-Cheng Chen and Xiaoren Li and Xiaotian Xu and Yun-Yuan Wang and Chen-Yu Liu | E24: misc | G24: Exclude | H24: EC4 | K24: Achieving high-performance computation on quantum systems presents a formidable challenge that necessitates bridging the capabilities between quantum hardware and classical computing resources. This study introduces an innovative distribution-aware Quantum-Classical-Quantum (QCQ) architecture, which integrates cutting-edge quantum software framework works with high-performance classical computing resources to address challenges in quantum simulation for materials and condensed matter physics. At the heart of this architecture is the seamless integration of VQE algorithms running on QPUs for efficient quantum state preparation, Tensor Network states, and QCNNs for classifying quantum states on classical hardware. For benchmarking quantum simulators, the QCQ architecture utilizes the cuQuantum SDK to leverage multi-GPU acceleration, integrated with PennyLane's Lightning plugin, demonstrating up to tenfold increases in computational speed for complex phase transition classification tasks compared to traditional CPU-based methods. This significant acceleration enables models such as the transverse field Ising and XXZ systems to accurately predict phase transitions with a 99.5% accuracy. The architecture's ability to distribute computation between QPUs and classical resources addresses critical bottlenecks in Quantum-HPC, paving the way for scalable quantum simulation. The QCQ framework embodies a synergistic combination of quantum algorithms, machine learning, and Quantum-HPC capabilities, enhancing its potential to provide transformative insights into the behavior of quantum systems across different scales. As quantum hardware continues to improve, this hybrid distribution-aware framework will play a crucial role in realizing the full potential of quantum computing by seamlessly integrating distributed quantum resources with the state-of-the-art classical computing infrastructure. | N24: http://arxiv.org/abs/2403.05828v2
A25: 24 | B25: Optimizing Quantum Convolutional Neural Network Architectures for Arbitrary Data Dimension | C25: Changwon Lee and Israel F Araujo and Dongha Kim and Junghan Lee and Siheon Park and Ju-Young Ryu and Daniel K Park | D25: Frontiers in Physics 13 1529188 (2025) | E25: article | F25: 10.3389/fphy.2025.1529188 | G25: Exclude | H25: EC7 | K25: Quantum convolutional neural networks (QCNNs) represent a promising approach in quantum machine learning, paving new directions for both quantum and classical data analysis. This approach is particularly attractive due to the absence of the barren plateau problem, a fundamental challenge in training quantum neural networks (QNNs), and its feasibility. However, a limitation arises when applying QCNNs to classical data. The network architecture is most natural when the number of input qubits is a power of two, as this number is reduced by a factor of two in each pooling layer. The number of input qubits determines the dimensions (i.e. the number of features) of the input data that can be processed, restricting the applicability of QCNN algorithms to real-world data. To address this issue, we propose a QCNN architecture capable of handling arbitrary input data dimensions while optimizing the allocation of quantum resources such as ancillary qubits and quantum gates. This optimization is not only important for minimizing computational resources, but also essential in noisy intermediate-scale quantum (NISQ) computing, as the size of the quantum circuits that can be executed reliably is limited. Through numerical simulations, we benchmarked the classification performance of various QCNN architectures when handling arbitrary input data dimensions on the MNIST and Breast Cancer datasets. The results validate that the proposed QCNN architecture achieves excellent classification performance while utilizing a minimal resource overhead, providing an optimal solution when reliable quantum computation is constrained by noise and imperfections. | N25: http://arxiv.org/abs/2403.19099v1
A26: 382 | B26: A HYBRID QUANTUM-INSPIRED CNN ARCHITECTURE FOR EFFICIENT AND ACCURATE BRAIN TUMOR CLASSIFICATION WITH EXPLAINABILITY ANALYSIS | C26: Sheethal and Amudha | D26: Journal of Theoretical and Applied Information Technology | E26: article | G26: Include | H26: QCNN for Brain Tumor Classification | I26: Exclude | J26: EC4 | K26: Brain tumors are considered one of the serious types of cancer and catching them early is crucial for better patient results. The use of Magnetic Resonance Imaging (MRI) plays a role in spotting and categorizing brain tumors; however, it can be tough and time consuming for radiologists to interpret these images. To address this issue, this study introduces a Quantum Inspired Convolutional Neural Network (QCNN) that integrates concepts from quantum mechanics, such as superposition and entanglement, with traditional Convolutional Neural Network (CNN) architectures. This innovative approach enhances feature extraction capabilities, allowing the model to recognize intricate patterns within MRI images more effectively. The QCNN achieved impressive results, reaching a peak validation accuracy of 99.44% and demonstrating significantly improved classification for various types of brain tumors, including Glioma and Meningitis. These findings highlight the potential of the QCNN framework to revolutionize tumor detection, offering radiologists a powerful tool that enhances diagnostic accuracy and efficiency in clinical practice, ultimately leading to better patient care and outcomes in the medical imaging field. © Little Lion Scientific.
A27: 26 | B27: Quantum Adjoint Convolutional Layers for Effective Data Representation | C27: Ren-Xin Zhao and Shi Wang and Yaonan Wang | E27: misc | F27: 10.1109/TCYB.2025.3567090 | G27: Exclude | H27: EC7 | K27: Quantum Convolutional Layer (QCL) is considered as one of the core of Quantum Convolutional Neural Networks (QCNNs) due to its efficient data feature extraction capability. However, the current principle of QCL is not as mathematically understandable as Classical Convolutional Layer (CCL) due to its black-box structure. Moreover, classical data mapping in many QCLs is inefficient. To this end, firstly, the Quantum Adjoint Convolution Operation (QACO) consisting of a quantum amplitude encoding and its inverse is theoretically shown to be equivalent to the quantum normalization of the convolution operation based on the Frobenius inner product while achieving an efficient characterization of the data. Subsequently, QACO is extended into a Quantum Adjoint Convolutional Layer (QACL) by Quantum Phase Estimation (QPE) to compute all Frobenius inner products in parallel. At last, comparative simulation experiments are carried out on PennyLane and TensorFlow platforms, mainly for the two cases of kernel fixed and unfixed in QACL. The results demonstrate that QACL with the insight of special quantum properties for the same images, provides higher training accuracy in MNIST and Fashion MNIST classification experiments, but sacrifices the learning performance to some extent. Predictably, our research lays the foundation for the development of efficient and interpretable quantum convolutional networks and also advances the field of quantum machine vision. | N27: http://arxiv.org/abs/2404.17378v1
A28: 27 | B28: Permutation-equivariant quantum convolutional neural networks | C28: Sreetama Das and Filippo Caruso | D28: Quantum Sci. Technol. 10 015030 (2025) | E28: article | F28: 10.1088/2058-9565/ad8e80 | G28: Exclude | H28: EC7 | K28: The Symmetric group $S_{n}$ manifests itself in large classes of quantum systems as the invariance of certain characteristics of a quantum state with respect to permuting the qubits. The subgroups of $S_{n}$ arise, among many other contexts, to describe label symmetry of classical images with respect to spatial transformations, e.g. reflection or rotation. Equipped with the formalism of geometric quantum machine learning, in this work we propose the architectures of equivariant quantum convolutional neural networks (EQCNNs) adherent to $S_{n}$ and its subgroups. We demonstrate that a careful choice of pixel-to-qubit embedding order can facilitate easy construction of EQCNNs for small subgroups of $S_{n}$. Our novel EQCNN architecture corresponding to the full permutation group $S_{n}$ is built by applying all possible QCNNs with equal probability, which can also be conceptualized as a dropout strategy in quantum neural networks. For subgroups of $S_{n}$, our numerical results using MNIST datasets show better classification accuracy than non-equivariant QCNNs. The $S_{n}$-equivariant QCNN architecture shows significantly improved training and test performance than non-equivariant QCNN for classification of connected and non-connected graphs. When trained with sufficiently large number of data, the $S_{n}$-equivariant QCNN shows better average performance compared to $S_{n}$-equivariant QNN . These results contribute towards building powerful quantum machine learning architectures in permutation-symmetric systems. | N28: http://arxiv.org/abs/2404.18198v1
A29: 28 | B29: Quanv4EO: Empowering Earth Observation by means of Quanvolutional Neural Networks | C29: Alessandro Sebastianelli and Francesco Mauro and Giulia Ciabatti and Dario Spiller and Bertrand Le Saux and Paolo Gamba and Silvia Ullo | E29: misc | G29: Exclude | H29: EC4 | K29: A significant amount of remotely sensed data is generated daily by many Earth observation (EO) spaceborne and airborne sensors over different countries of our planet. Different applications use those data, such as natural hazard monitoring, global climate change, urban planning, and more. Many challenges are brought by the use of these big data in the context of remote sensing applications. In recent years, employment of machine learning (ML) and deep learning (DL)-based algorithms have allowed a more efficient use of these data but the issues in managing, processing, and efficiently exploiting them have even increased since classical computers have reached their limits. This article highlights a significant shift towards leveraging quantum computing techniques in processing large volumes of remote sensing data. The proposed Quanv4EO model introduces a quanvolution method for preprocessing multi-dimensional EO data. First its effectiveness is demonstrated through image classification tasks on MNIST and Fashion MNIST datasets, and later on, its capabilities on remote sensing image classification and filtering are shown. Key findings suggest that the proposed model not only maintains high precision in image classification but also shows improvements of around 5\% in EO use cases compared to classical approaches. Moreover, the proposed framework stands out for its reduced parameter size and the absence of training quantum kernels, enabling better scalability for processing massive datasets. These advancements underscore the promising potential of quantum computing in addressing the limitations of classical algorithms in remote sensing applications, offering a more efficient and effective alternative for image data classification and analysis. | N29: http://arxiv.org/abs/2407.17108v1
A30: 29 | B30: Statistical Analysis of the Impact of Quaternion Components in Convolutional Neural Networks | C30: Gerardo Altamirano-Gómez and Carlos Gershenson | E30: misc | G30: Exclude | H30: EC4 | K30: In recent years, several models using Quaternion-Valued Convolutional Neural Networks (QCNNs) for different problems have been proposed. Although the definition of the quaternion convolution layer is the same, there are different adaptations of other atomic components to the quaternion domain, e.g., pooling layers, activation functions, fully connected layers, etc. However, the effect of selecting a specific type of these components and the way in which their interactions affect the performance of the model still unclear. Understanding the impact of these choices on model performance is vital for effectively utilizing QCNNs. This paper presents a statistical analysis carried out on experimental data to compare the performance of existing components for the image classification problem. In addition, we introduce a novel Fully Quaternion ReLU activation function, which exploits the unique properties of quaternion algebra to improve model performance. | N30: http://arxiv.org/abs/2409.00140v1
A31: 330 | B31: A new quantum AI -performance analysis of low-power VLSI circuits in IoT devices using quantum machine learning techniques | C31: Manan Mujahid Md and Deepa Jose | D31: Quantum Information Processing | E31: article | F31: 10.1007/s11128-026-05149-6 | G31: Maybe | H31: Check QCNN results | I31: Exclude | J31: EC8 | K31: Recent advancements in the Internet of Things (IoT) have heightened the demand for energy efficient, high-performance Very Large-Scale Integration (VLSI) circuits. While machine learning has been widely employed for performance analysis and optimization, the integration of quantum computing concepts is reshaping this domain. This paper presents a comprehensive framework that leverages both classical deep learning and quantum-enhanced algorithms to analyze and optimize low-power VLSI circuits in IoT devices. Advanced Quantum AI techniques—specifically, the Proposed Quantum Support Vector Machine (QSVM)—are applied alongside conventional models (QANN, QCNN, QLSTM, and QAdaptive CNN-LSTM) to enable high-dimensional feature transformations and exponential parallelism in analysis. Experimental results demonstrate that the QAdaptive CNN-LSTM achieves 94.5% accuracy, 92.0% precision, 93.0% recall, 92.5% F1-score, and an MSE of 0.05, significantly outperforming QANN (82.5% accuracy, 81.2% precision, 81.0% recall, 81.1% F1, MSE 0.15), QCNN (86.5% accuracy, 84.0% precision, 81.5% recall, 82.7% F1, MSE 0.11), and QLSTM (84.0% accuracy, 83.5% precision, 85.5% recall, 84.5% F1, MSE 0.20). Moreover, the Proposed QSVM model attains the highest accuracy of 96.0%, with 94.5% precision, 95.0% recall, 94.7% F1-score, and the lowest MSE of 0.035, underscoring the strong potential of quantum-enhanced learning in VLSI analysis. These quantifiable improvements translate into superior prediction accuracy, faster convergence, and better energy-timing optimization under resource-constrained IoT scenarios. The hybrid quantum–classical analytical approach not only enhances predictive maintenance and optimization of VLSI circuits but also accelerates the development of sustainable, scalable, and energy-efficient IoT ecosystems. © The Author(s), under exclusive licence to Springer Science+Business Media, LLC, part of Springer Nature 2026.
A32: 268 | B32: A New Quantum Circuits of Quantum Convolutional Neural Network for X-Ray Images Classification | C32: Mohammed Yousif and Belal Al-Khateeb and Begonya Garcia-Zapirain | D32: IEEE Access | E32: article | F32: 10.1109/ACCESS.2024.3396411 | G32: Include | H32: QCNN for X-Ray Classification | K32: A common model for classifying images is the convolutional neural network (CNN), which has the benefit of effectively using data correlation information. Despite their remarkable success, classical CNNs may face challenges in achieving further improvements in accuracy, computational efficiency, explainability, and generalization. However, if the specified data dimension or model grows too large, CNN becomes difficult to train effectively with a slowdown processing. In order to address a problem using CNN utilizing quantum computing, Quantum Convolutional Neural Network (QCNN) proposes a novel quantum solution or enhances the functionality of an existing learning model in terms of processing time during training. This paper presents a comparative analysis between classical Convolutional Neural Networks (CNNs) and a novel quantum circuit architecture tailored for image-based tasks, emphasizing the adaptability and versatility of quantum circuits in enhancing feature extraction capabilities and then final accuracy and processing time. A MNIST and covidx-cxr3 datasets was used to train quantum-CNN models, and the results of these comparisons were made with traditional CNN performance. The results demonstrate that the suggested QCNN beat the traditional CNN in terms of recognition accuracy and processing speed (process time) when combined with cutting-edge feature extraction techniques. This superiority is particularly evident when trained on the covidx-cxr3 dataset, highlighting the potential for quantum computing to revolutionize image classification tasks. © 2013 IEEE.
A33: 32 | B33: QuFeX: Quantum feature extraction module for hybrid quantum-classical deep neural networks | C33: Naman Jain and Amir Kalev | D33: Quantum Sci. Technol. 11 015017 (2026) | E33: article | F33: 10.1088/2058-9565/ae24a8 | G33: Exclude | H33: EC4 | K33: We introduce Quantum Feature Extraction (QuFeX), a novel quantum machine learning module. The proposed module enables feature extraction in a reduced-dimensional space, significantly decreasing the number of parallel evaluations required in typical quantum convolutional neural network architectures. Its design allows seamless integration into deep classical neural networks, making it particularly suitable for hybrid quantum-classical models. As an application of QuFeX, we propose Qu-Net -- a hybrid architecture which integrates QuFeX at the bottleneck of a U-Net architecture. The latter is widely used for image segmentation tasks such as medical imaging and autonomous driving. Our numerical analysis indicates that the Qu-Net can achieve superior segmentation performance compared to a U-Net baseline. These results highlight the potential of QuFeX to enhance deep neural networks by leveraging hybrid computational paradigms, providing a path towards a robust framework for real-world applications requiring precise feature extraction. | N33: http://arxiv.org/abs/2501.13165v2
A34: 475 | B34: A Novel Approach to Derma Quantum (Skin Disease Detection and Classification Using ResNet50 and QCNN) | C34: Harsh Kumar and Pranesh Sharma and Ajina and Nithin M Kannal and Ujjwal Kumar | D34: 2024 2nd International Conference on Computing and Data Analytics, ICCDA 2024 - Proceedings | E34: inproceedings | F34: 10.1109/ICCDA64887.2024.10867304 | G34: Include | H34: QCNN with ResNet for Skin Diseases | K34: Multiclass disease classification is a crucial task in medical diagnostics, but achieving high accuracy across diverse disease categories remains challenging. This paper presents a novel approach that integrates Quantum Convolutional Neural Networks (QCNN) with the ResNet architecture to enhance multiclass skin disease classification. The model utilizes quantum computing principles to improve feature extraction and classification performance. We evaluate the model on a dataset comprising 16 skin disease classes from the DermNet dataset, covering both common and rare conditions like acne, melanoma, Eczema, Seborrheic Keratoses, Tinea Ringworm, Bullous disease, Poison Ivy, Psoriasis, Vascular Tumors, etc. Experimental results demonstrate that our QCNN-ResNet model achieves a classification accuracy of 86%, significantly surpassing the 66% accuracy of traditional ResNet models. This improvement is attributed to the enhanced feature representation provided by quantum layers, which capture complex patterns in medical images more effectively. Furthermore, the model exhibits robustness to noisy data, maintaining high accuracy across varying image quality levels. These findings highlight the potential of quantumenhanced neural networks in advancing medical diagnostics. Future research will explore scaling the model to larger datasets and extending its application to other medical imaging domains. © 2024 IEEE.
A35: 449 | B35: A Novel Framework For Brain Disease Classification Using Quantum Convolutional Neural Network | C35: Sanskriti Chandra and Shivam Saxena and Santosh Kumar and Mithilesh Kumar Chaube and Narendra Kuber Bodhey | D35: Proceedings of 2022 IEEE International Women in Engineering (WIE) Conference on Electrical and Computer Engineering, WIECON-ECE 2022 | E35: inproceedings | F35: 10.1109/WIECON-ECE57977.2022.10150851 | G35: Include | H35: QCNN for Brain Disease Classification | K35: More than 3,410 children and teens (under the age of 20) in India suffer from catastrophic brain disorders and the creation of abnormal brain cells each year, according to recent reports on the country's rapid increase in brain ailments. It is difficult to quantify the survival rate of human patients due to the rarity, variability, and abnormal development of tumors. These patients cannot be accurately predicted using machine learning approaches for early diagnosis. These methods need a huge amount of discriminatory information and processing time based on annotated limited brain image datasets to classify diseases. To solve this problem, we proposed a novel model based on Quantum Convolutional Neural Network techniques for early diagnosis of tumors in a less invasive manner that may reduce the number of operations and more precisely define the kind of therapy needed. The proposed framework uses image processing techniques to remove noise and other specific artifacts from the brain images. After that, the processed images are segmented into distinct regions of interest using machine learning techniques. The suggested framework uses deep quantum approaches to identify brain disorders based on extracted discriminating characteristics from the brain images, such as textures and qubit features, enabling reliable prediction of brain disorders. The proposed system provided 93.99% accuracy for the accurate prediction of brain diseases using classical models and 88.7% accuracy using the Quantum Convolutional Neural Network (QCNN) model. © 2022 IEEE.
